Workbook

Sheet Categories
B1: 1 | C1: 2 | D1: 3 | F1: 4 | G1: 5 | H1: 6
B2: TECHNIQUE LEVEL | C2: EXERCISE NAME | D2: EXERCISE TOOL | F2: UNIT TÍNH | G2: EXERCISE TYPE | H2: MUSCLE TYPE | J2: MOVEMENT
E3: Bodyweight | F3: (Theo bodyweight người tập) | G3: Cardio | H3: Chest | J3: Push | Press
E4: Resistance Band | F4: (Theo mức dây band) | G4: Hypertrophy | H4: Triceps | J4: Vertical Pull
D5: Free Weight | E5: Barbell | F5: (Theo Plate tạ) | G5: Stability | H5: Deltoid | J5: Horizontal Pull
E6: Plate | F6: (Theo mức Plate tạ) | G6: Power | H6: Trap
E7: Dumbbell | F7: (Theo mức tạ dumbbell) | G7: Warm-up | H7: Lats
E8: Kettlebell | F8: (Theo mức tạ kettlebell) | G8: Strength | H8: Biceps
E9: Ez Bar | F9: (Theo mức plates trên machine) | G9: Endurance | H9: Quads
D10: Weighted Machine | E10: Cable Machine | G10: Mobility | H10: Adductor
E11: Power Rack | H11: Glutes
E12: Dual Lat Machine | H12: Hamstrings
E13: Standing Calf Raise Machine | H13: Calves
E14: Leg Press Machine | H14: Upper Back
E15: Leg Curl Machine | H15: Abdominals
E16: Leg Extension | H16: Abductors
E17: Chest Fly Machine | H17: Forearms
E18: Seated Calf Raise Machine | H18: Lower Back
E19: Back Extension Machine
D24: Cardio Machine | E24: Bicycle Machine
E25: Rowing Machine
E26: Stair Climber Machine
E27: Treadmill
D30: Others | E30: Ab Wheel
E31: Medicine Ball
E32: Box
E33: Farmers Walk Handles
E34: Sled Push
E35: Jump rope
E36: Supension
E37: Slant Board
E38: Trap Bar
E39: Med Ball
E40: Smith Machine
E41: Swiss Ball
E42: GHD Machine
... E44: Battle Rope

Sheet Exercise Library
B1: Nguyên khúc này là để phân loại, filter, tìm exercise dễ hơn khi lên Program cho khách / cho mình | K1: Cách tính volumn unit A | N1: Cách tính Volumn unit Ax trên từng nhóm cơ, ở từng bài tập
E2: Mỗi exercise có thể có <= 3 exercise type. Thứ tự ưu tiên = nhau. | H2: Mỗi exercise có thể có <= 3 muscle type chính Thứ tự ưu tiên = nhau. | K2: A = SET * REPS | N2: A1 = A * 100% nếu A1 là Primary A1 = A * 50% nếu A1 là Secondary A1 = A * 33,33% nếu A1 là Teriary A1 = A * 25% nếu A1 là Quarter Tổng volumn unit trên từng nhóm cơ, ở tất cả các bài tập B = tổng all A1
K3: SET | L3: REPS | M3: LOAD | N3: VOLUMN UNIT BY MUSCLE GROUP
B4: EXERCISE INFORMATION | E4: CATEGORIES BY EXERCISE TYPE | H4: CATEGORIES BY MUSCLE TYPE | N4: CHEST | O4: DELTOID | P4: TRAP | Q4: BICEPS | R4: TRICEPS | S4: UPPER BACK | T4: LOWER BACK | U4: SERRATUS ANTERIOR | V4: LAT | W4: QUADS | X4: ADDUCTOR | Y4: GLUTES | Z4: HAMSTRING | AA4: ABDOMINALS | AC4: CALF
B5: TECHNIQUE LEVEL | C5: EXERCISE | D5: TOOL | E5: EXERCISE TYPE | F5: EXERCISE TYPE | G5: EXERCISE TYPE | H5: MUSCLE TYPE | I5: MUSCLE TYPE | J5: MUSCLE TYPE | K5: Mỗi exercise có thể được perform nhiều set trong 1 tuần, từ 0 - 50 | L5: Mỗi set có thể có nhiều rep, từ 1 - 50 | M5: Load là số kg tạ được sử dụng cho mỗi set bài tập | N5: A1 | O5: A2 | P5: A3 | Q5: A4 | R5: A5 | S5: A6 | T5: A7 | U5: A8 | V5: A9 | W5: A10 | X5: A11 | Y5: A12 | Z5: A13 | AA5: A14 | AB5: A15 | AC5: A16
A6: 1 | B6: Easy | C6: Standing Low Pulley Chest Press (Cable) | D6: Cable Machine | E6: Hypertrophy | H6: Chest | N6: P | O6: S | R6: S | U6: Z
A7: 2 | B7: Easy | C7: Standing Mid Pulley Chest Press (Cable) | D7: Cable Machine | E7: Hypertrophy | H7: Chest | N7: P | O7: S | R7: S | U7: Z
A8: 3 | B8: Easy | C8: Standing high Pulley Chest Press (Cable) | D8: Cable Machine | E8: Hypertrophy | H8: Chest | N8: P | O8: S | R8: S | U8: Z
A9: 4 | B9: Intermediate | C9: Flat Chest Press (Dumbbell) | D9: Dumbbell | E9: Hypertrophy | F9: Strength | H9: Chest | N9: P | O9: S | R9: S | U9: Z
A10: 5 | B10: Intermediate | C10: Incline Chest Press (Dumbbell) | D10: Dumbbell | E10: Hypertrophy | F10: Strength | H10: Chest | N10: P | O10: S | R10: S | U10: Z
A11: 6 | B11: Intermediate | C11: Decline Chest Press (Dumbbell) | D11: Dumbbell | E11: Hypertrophy | F11: Strength | H11: Chest | N11: P | O11: S | R11: S | U11: Z
A12: 7 | B12: Advanced | C12: Decline Chest Press (Barbell) | D12: Barbell | E12: Strength | F12: Hypertrophy | H12: Chest | N12: P | O12: S | R12: S | U12: Z
A13: 8 | B13: Advanced | C13: Incline Chest Press (Barbell) | D13: Barbell | E13: Strength | F13: Hypertrophy | H13: Chest | N13: P | O13: S | R13: S | U13: Z
A14: 9 | B14: Advanced | C14: Decline Chest Press (Barbell) | D14: Barbell | E14: Strength | F14: Hypertrophy | H14: Chest | N14: P | O14: S | R14: S | U14: Z
A15: 10 | B15: Easy | C15: Standing Low Pulley Chest Fly (Cable) | D15: Cable Machine | E15: Hypertrophy | H15: Chest | N15: P | O15: S | Q15: S | U15: Z
A16: 11 | B16: Easy | C16: Standing Mid Pulley Chest Fly (Cable) | D16: Cable Machine | E16: Hypertrophy | H16: Chest | N16: P | O16: S | Q16: S | U16: Z
A17: 12 | B17: Easy | C17: Standing high Pulley Chest Fly (Cable) | D17: Cable Machine | E17: Hypertrophy | H17: Chest | N17: P | O17: S | Q17: S | U17: Z
A18: 13 | B18: Easy | C18: Pec Dec (Chest Fly Machine) | D18: Chest Fly Machine | E18: Hypertrophy | H18: Chest | N18: P | O18: S | Q18: S | U18: Z
A19: 14 | B19: Intermediate | C19: Flat Chest Fly (Dumbbell) | D19: Dumbbell | E19: Hypertrophy | H19: Chest | N19: P | O19: S | Q19: S | U19: Z
A20: 15 | B20: Intermediate | C20: Incline Chest Fly (Dumbbell) | D20: Dumbbell | E20: Hypertrophy | H20: Chest | N20: P | O20: S | Q20: S | U20: Z
A21: 16 | B21: Intermediate | C21: Decline Chest Fly (Dumbbell) | D21: Dumbbell | E21: Hypertrophy | H21: Chest | N21: P | O21: S | Q21: S | U21: Z
A22: 17 | B22: Intermediate | C22: Suspension Chest Fly (Supension) | D22: Supension | E22: Hypertrophy | F22: Stability | H22: Chest | N22: P | O22: S | Q22: S | U22: Z
A23: 18 | B23: Easy | C23: Assisted Dip (Band) | D23: Resistance Band | E23: Hypertrophy | F23: Strength | H23: Triceps | N23: S | O23: S | R23: P | U23: Z
A24: 19 | B24: Intermediate | C24: Dip (Body Weight) | D24: Bodyweight | E24: Hypertrophy | F24: Strength | H24: Triceps | N24: S | O24: S | R24: P | U24: Z
A25: 20 | B25: Advanced | C25: Weighted Dip (Plate) | D25: Plate | E25: Hypertrophy | F25: Strength | H25: Triceps | N25: S | O25: S | R25: P | U25: Z
A26: 21 | B26: Easy | C26: Band Assisted Push up (Band) | D26: Resistance Band | E26: Hypertrophy | F26: Strength | H26: Chest | N26: P | O26: S | R26: S | U26: Z | AA26: C
A27: 22 | B27: Intermediate | C27: Normal Push up (Bodyweight) | D27: Bodyweight | E27: Hypertrophy | F27: Strength | H27: Chest | N27: P | O27: S | R27: S | U27: Z | AA27: C
A28: 23 | B28: Intermediate | C28: Kneeling Push up (Bodyweight) | D28: Bodyweight | E28: Hypertrophy | F28: Strength | H28: Chest | N28: P | O28: S | R28: S | U28: Z
A29: 24 | B29: Intermediate | C29: Box Push up (Bodyweight) | D29: Bodyweight | E29: Hypertrophy | F29: Strength | H29: Chest | N29: P | O29: S | R29: S | U29: Z
A30: 25 | B30: Intermediate | C30: Counter Push up (Bodyweight) | D30: Bodyweight | E30: Hypertrophy | F30: Strength | H30: Chest | N30: P | O30: S | R30: S | U30: Z
A31: 26 | B31: Advanced | C31: Band Push up (Plate) | D31: Plate | E31: Hypertrophy | F31: Strength | H31: Chest | N31: P | O31: S | R31: S | U31: Z | AA31: C
A32: 27 | B32: Advanced | C32: Plate Push up (Plate) | D32: Plate | E32: Hypertrophy | F32: Strength | H32: Chest | N32: P | O32: S | R32: S | U32: Z | AA32: C
A33: 28 | B33: Advanced | C33: Chain Push up (Plate) | D33: Plate | E33: Hypertrophy | F33: Strength | H33: Chest | N33: P | O33: S | R33: S | U33: Z | AA33: C
A34: 29 | B34: Easy | C34: Shoulder Press (Dumbbell) | D34: Dumbbell | E34: Hypertrophy | F34: Strength | H34: Deltoid | O34: P
A35: 30 | B35: Easy | C35: Should Press (Barbell) | D35: Barbell | E35: Hypertrophy | F35: Strength | H35: Deltoid | O35: P
A36: 31 | B36: Easy | C36: Shoulder Press (Smith Machine) | D36: Smith Machine | E36: Hypertrophy | F36: Strength | H36: Deltoid | O36: P | R36: S | U36: C
A37: 32 | B37: Easy | C37: Shoulder Press (Cable Machine) | D37: Cable Machine | E37: Hypertrophy | F37: Strength | H37: Deltoid | O37: P | R37: S | U37: C
A38: 33 | B38: Intermediate | C38: Seated Shoulder Press (Dumbbell) | D38: Dumbbell | E38: Hypertrophy | F38: Strength | H38: Deltoid | O38: P | R38: S | U38: C
A39: 34 | B39: Intermediate | C39: Standing Shoulder Press (Dumbbell) | D39: Dumbbell | E39: Hypertrophy | F39: Strength | H39: Deltoid | O39: P
A40: 35 | B40: Intermediate | C40: Seated One Arm Shoulder Press (Dumbbell) | D40: Dumbbell | E40: Hypertrophy | F40: Strength | G40: Stability | H40: Deltoid | O40: P | R40: S | U40: C
...

Sheet Client Profile
B3: CLIENT PROFILE THÔNG TIN KHÁCH HÀNG
B5: CLIENT INFORMATION -- THÔNG TIN KHÁCH HÀNG
B7: Full Name Họ & Tên | F7: Contact Thông tin liên hệ
B8: D.O.B Ngày sinh | F8: Start Date Ngày thực hiện
B11: ASSESSMENT STRUCTURE -- CẤU TRÚC CHƯƠNG TRÌNH THẨM ĐỊNH
H12: TO DO TODAY
B13: 1 | C13: LIFESTYLE -- LỐI SỐNG (THÓI QUEN, BỆNH LÝ, CHẤN THƯƠNG, DINH DƯỠNG, GIẤC NGỦ, STRESS) | H13: FALSE
B14: 2 | C14: FUNCTIONAL MOVEMENT -- CHUYỂN ĐỘNG CƠ BẢN | H14: FALSE
B15: 3 | C15: BODY ASSESSMENT -- CẤU TRÚC CƠ THỂ | H15: FALSE
B16: 4 | C16: BODY PHYSIQUE -- THỂ HÌNH & SỐ ĐO CƠ THỂ | H16: FALSE
B17: 5 | C17: CARDIOVASCULAR & ENDURANCE -- SỨC BỀN & SỨC KHOẺ TIM MẠCH | H17: FALSE
B18: 6 | C18: SPORT SPECIFIC TEST -- ĐỘNG TÁC THỂ THAO CỤ THỂ | H18: FALSE
B21: GOAL SETTING -- XÁC ĐỊNH MỤC TIÊU
F23: NOTES -- GHI CHÚ
B24: Long Term Goal Mục tiêu dài hạn | C24: Xây dựng một lối sống lành mạnh, một active lifestyle,
B26: Short Term Goal Mục tiêu ngắn hạn | C26: Bắt đầu 1 nutrition plan trong vòng 12 tuần,tăng cơ giảm mỡ, compete được ở Hyrox
B28: Progress Measurement Method Phương pháp đánh giá tiến độ và kết quả | F28: Select one -- Chọn 1
C29: Body Composition (BEFORE/AFTER photo) Thay đổi về hình thể (Hình BEFORE/AFTER) | F29: FALSE
C30: Body Weight Change Thay đổi về cân nặng | F30: FALSE
C31: Posture (BEFORE/AFTER photo) Thay đổi về tư thế (Hình BEFORE/AFTER) | F31: FALSE
C32: Flexibility improvement (Muscle length test) Thay đổi về sự dẻo dai (Muscle lenghth test) | F32: FALSE
C33: Movement improvement (OHS test) Thay đổi về sự dẻo dai & chuyển động linh hoạt | F33: FALSE
C34: Enduration (VO2 Max) Thay đổi về sức bền (VO2 Max) | F34: FALSE
C35: PR Test on Squat / Bench / Deadlift Test mực tổng cử cá nhân cao nhất | F35: FALSE
C36: Conditioning Test (Selected movement) Thay đổi về sức bền và sự linh hoạt | F36: FALSE
C37: Customised S&C Test for sport specific Bài test được thiết kế cá nhân dựa trên môn thể thao | F37: FALSE
C38: Notes -- Ghi chú về bài test
B43: FIRST ASSESSMENT CHƯƠNG TRÌNH THẨM ĐỊNH CƠ THỂ
A45: 1 | B45: LIFESTYLE -- LỐI SỐNG | F45: LIFESTYLE -- LỐI SỐNG
B46: STRESS MANAGEMENT -- QUẢN LÝ ÁP LỰC | F46: MEDICAL & INJURY -- BỆNH LÝ & CHẤN THƯƠNG
B48: What are your sources of stress Các vấn đề hiện tại khiến gặp bạn stress là gì? | F48: Do you have any pre-existing medical conditions? Bạn có bệnh lý nào hiện tại hoặc đã chữa khỏi không?
B50: What do you do to recover from that stress? Bạn thường giải quyết stress bằng cách nào? | F50: Did you have any physical injuries before? Bạn đã bị chấn thương bao giờ chưa? Ở bộ phận nào trên cơ thể?
B52: What is the state of your mental health, and have you suffered from any mental health conditions such as anxiety or depression? Tình trạng sức khỏe tâm thần của bạn như thế nào và bạn có gặp phải bất kỳ vấn đề gì không? | F52: Do you have any doctor recommendation for physical activities? Bạn có đề nghị nào của bác sĩ về việc tập luyện?
B55: LIFESTYLE -- LỐI SỐNG | F55: LIFESTYLE -- LỐI SỐNG
B56: NUTRITION -- DINH DƯỠNG | F56: DAILY HABIT -- THÓI QUEN THƯỜNG NHẬT
B58: Describe how you usually eat during a day Miêu tả các bữa ăn hiện tại của bạn mỗi ngày | F58: Does your job introduce potential barriers to healthy eating? Tính chất công việc hoặc cuộc sống hiện tại có khiến bạn gặp khó khăn trong việc giữ chế độ ăn uống lành mạnh?
B59: Meal 1
B61: Meal 2 | F61: Are you getting enough quality sleep? Bạn có ngủ đủ chất lượng không? Nếu không hãy cho biết thời gian bạn ngủ một ngày?
B63: Meal 3 | F63: Do you play any other sports or physical activities? Bạn có đang tham gia hoạt động hoặc môn thể thao nào khác không?
B66: Describe types of food you like Miêu tả các loại thực phẩm ưu thích của bạn
...

Sheet Tracking
B18: DAILY | G18: WEEKLY
B19: Date | C19: Bodyweight (KG) | D19: Cardio (minutes) | E19: Steps (step) | G19: Date | H19: Body Measurement (cm) | M19: Photograph
H20: Bicep | I20: Chest | J20: Waist | K20: Hips | L20: Thigh | M20: Front | N20: Back | O20: Side
B21: 46054 | M21: FALSE | N21: FALSE | O21: FALSE
B22: =B21+1 | M22: FALSE | N22: FALSE | O22: FALSE
B23: =B22+1 | M23: FALSE | N23: FALSE | O23: FALSE
B24: =B23+1 | M24: FALSE | N24: FALSE | O24: FALSE
B25: =B24+1 | M25: FALSE | N25: FALSE | O25: FALSE
B26: =B25+1 | M26: FALSE | N26: FALSE | O26: FALSE
B27: =B26+1 | M27: FALSE | N27: FALSE | O27: FALSE
B28: =B27+1 | M28: FALSE | N28: FALSE | O28: FALSE
B29: =B28+1 | M29: FALSE | N29: FALSE | O29: FALSE
B30: =B29+1 | M30: FALSE | N30: FALSE | O30: FALSE
B31: =B30+1 | M31: FALSE | N31: FALSE | O31: FALSE
B32: =B31+1 | M32: FALSE | N32: FALSE | O32: FALSE
B33: =B32+1 | M33: FALSE | N33: FALSE | O33: FALSE
... B121: =B120+1 | M121: FALSE | N121: FALSE | O121: FALSE

Sheet Training Plan 1
B1: TRAINING PLAN | E1: 12 WEEK
B2: CLIENT | C2: ='Client Profile'!C7 | E2: COACH | F2: Long Chu
B4: PHASE 1 | C4: WEEK 1 -> 4 | H4: 1-A | O4: 1-B | V4: 1-C | AC4: 1-D
C5: Workout | E5: Cardio / Sport | F5: Steps | H5: Exercise | I5: Set | J5: Rep | K5: RIR | L5: Tempo | M5: Rest | P5: Set | Q5: Rep | R5: RIR | S5: Tempo | T5: Rest | V5: Exercise | W5: Set | X5: Rep | Y5: RIR | Z5: Tempo | AA5: Rest | AC5: Exercise | AD5: Set | AE5: Rep | AF5: RIR | AG5: Tempo | AH5: Rest
B6: Day 1 | D6: 1-A | E6: 30 Phút | F6: 5000 - 7000
B7: Day 2 | F7: 5000 - 7000
B8: Day 3 | D8: 1-B | E8: 30 Phút | F8: 5000 - 7000
B9: Day 4 | F9: 5000 - 7000
B10: Day 5 | D10: 1-C | E10: 30 Phút | F10: 5000 - 7000
B11: Day 6 | F11: 5000 - 7000
B12: Day 7 | D12: 1-D | E12: 30 Phút | F12: 5000 - 7000
B14: PHASE 2 | C14: WEEK 5 -> 8 | H14: 2-A | O14: 2-B | V14: 2-C | AC14: 2-D
C15: Workout | E15: Running | F15: Steps | H15: Exercise | I15: Set | J15: Rep | K15: RIR | L15: Tempo | M15: Rest | O15: Exercise | P15: Set | Q15: Rep | R15: RIR | S15: Tempo | T15: Rest | V15: Exercise | W15: Set | X15: Rep | Y15: RIR | Z15: Tempo | AA15: Rest | AC15: Exercise | AD15: Set | AE15: Rep | AF15: RIR | AG15: Tempo | AH15: Rest
B16: Day 1 | C16: Push | D16: 2-A | E16: Easy Run
B17: Day 2 | E17: Interval
B18: Day 3 | C18: Pull | D18: 2-B
B19: Day 4 | C19: Leg | D19: 2-C | E19: Tempo Run
B20: Day 5
B21: Day 6 | C21: Full Body | D21: 2-D
B22: Day 7 | E22: Long Run
B24: PHASE 3 | C24: WEEK 9 -> 12 | H24: 3-A | O24: 3-B | V24: 3-C | AC24: 3-D
C25: Workout | E25: Cardio / Sport | F25: Steps | H25: Exercise | I25: Set | J25: Rep | K25: RIR | L25: Tempo | M25: Rest | O25: Exercise | P25: Set | Q25: Rep | R25: RIR | S25: Tempo | T25: Rest | V25: Exercise | W25: Set | X25: Rep | Y25: RIR | Z25: Tempo | AA25: Rest | AC25: Exercise | AD25: Set | AE25: Rep | AF25: RIR | AG25: Tempo | AH25: Rest
B26: Day 1 | C26: Squat | D26: 3-A
B27: Day 2
B28: Day 3 | C28: Bench | D28: 3-B
B29: Day 4 | C29: Deadlift | D29: 3-C
B30: Day 5
B31: Day 6 | C31: Full body | D31: 3-D
B32: Day 7
B35: General
B45: Note về bài tập

Sheet 1-A
A1: PHASE 1 | C1: WORKOUT 1-A
A3: Session Check-in
A4: WEEK
A5: 1
A6: 2
A7: 3
A8: 4
A12: Exercise | F12: Set | G12: Rep | H12: RIR | I12: Tempo | J12: Rest
A13: ='Training Plan 1'!H6 | F13: ='Training Plan 1'!I6 | G13: ='Training Plan 1'!J6 | H13: ='Training Plan 1'!K6 | I13: ='Training Plan 1'!L6 | J13: ='Training Plan 1'!M6
A14: WEEK | B14: DATE | C14: SET 1 | E14: SET 2 | G14: SET 3 | I14: SET 4 | K14: TOTAL VOLUMN | L14: NOTES
C15: REP | D15: LOAD | E15: REP | F15: LOAD | G15: REP | H15: LOAD | I15: REP | J15: LOAD
A16: 1 | B16: =B5 | K16: =C16*D16+E16*F16+G16*H16+I16*J16
A17: 2 | B17: =B6 | K17: =C17*D17+E17*F17+G17*H17+I17*J17
A18: 3 | B18: =B7 | K18: =C18*D18+E18*F18+G18*H18+I18*J18
A19: 4 | B19: =B8 | K19: =C19*D19+E19*F19+G19*H19+I19*J19
B20: =B9 | K20: =C20*D20+E20*F20+G20*H20+I20*J20
B21: =B10 | K21: =C21*D21+E21*F21+G21*H21+I21*J21
A23: Exercise | F23: Set | G23: Rep | H23: RIR | I23: Tempo | J23: Rest
A24: ='Training Plan 1'!H7 | F24: ='Training Plan 1'!I7 | G24: ='Training Plan 1'!J7 | H24: ='Training Plan 1'!K7 | I24: ='Training Plan 1'!L7 | J24: ='Training Plan 1'!M7
A25: WEEK | B25: DATE | C25: SET 1 | E25: SET 2 | G25: SET 3 | I25: SET 4 | K25: TOTAL VOLUMN | L25: NOTES
C26: REP | D26: LOAD | E26: REP | F26: LOAD | G26: REP | H26: LOAD | I26: REP | J26: LOAD
A27: 1 | B27: =B16 | K27: =C27*D27+E27*F27+G27*H27+I27*J27
A28: 2 | B28: =B17 | K28: =C28*D28+E28*F28+G28*H28+I28*J28
A29: 3 | B29: =B18 | K29: =C29*D29+E29*F29+G29*H29+I29*J29
A30: 4 | B30: =B19 | K30: =C30*D30+E30*F30+G30*H30+I30*J30
B31: =B20 | K31: =C31*D31+E31*F31+G31*H31+I31*J31
B32: =B21 | K32: =C32*D32+E32*F32+G32*H32+I32*J32
A34: Exercise | F34: Set | G34: Rep | H34: RIR | I34: Tempo | J34: Rest
A35: ='Training Plan 1'!H8 | F35: ='Training Plan 1'!I8 | G35: ='Training Plan 1'!J8 | H35: ='Training Plan 1'!K8 | I35: ='Training Plan 1'!L8 | J35: ='Training Plan 1'!M8
A36: WEEK | B36: DATE | C36: SET 1 | E36: SET 2 | G36: SET 3 | I36: SET 4 | K36: TOTAL VOLUMN | L36: NOTES
C37: REP | D37: LOAD | E37: REP | F37: LOAD | G37: REP | H37: LOAD | I37: REP | J37: LOAD
A38: 1 | B38: =B27 | K38: =C38*D38+E38*F38+G38*H38+I38*J38
A39: 2 | B39: =B28 | K39: =C39*D39+E39*F39+G39*H39+I39*J39
A40: 3 | B40: =B29 | K40: =C40*D40+E40*F40+G40*H40+I40*J40
A41: 4 | B41: =B30 | K41: =C41*D41+E41*F41+G41*H41+I41*J41
B42: =B31 | K42: =C42*D42+E42*F42+G42*H42+I42*J42
B43: =B32 | K43: =C43*D43+E43*F43+G43*H43+I43*J43
A45: Exercise | F45: Set | G45: Rep | H45: RIR | I45: Tempo | J45: Rest
A46: ='Training Plan 1'!H9 | F46: ='Training Plan 1'!I9 | G46: ='Training Plan 1'!J9 | H46: ='Training Plan 1'!K9 | I46: ='Training Plan 1'!L9 | J46: ='Training Plan 1'!M9
A47: WEEK | B47: DATE | C47: SET 1 | E47: SET 2 | G47: SET 3 | I47: SET 4 | K47: TOTAL VOLUMN | L47: NOTES
...

Sheet 1-B
A1: PHASE 1 | C1: WORKOUT 1-B
A3: Session Check-in
A4: WEEK
A5: 1
A6: 2
A7: 3
A8: 4
A12: Exercise | F12: Set | G12: Rep | H12: RIR | I12: Tempo | J12: Rest
A13: ='Training Plan 1'!O6 | F13: ='Training Plan 1'!P6 | G13: ='Training Plan 1'!Q6 | H13: ='Training Plan 1'!R6 | I13: ='Training Plan 1'!S6 | J13: ='Training Plan 1'!T6
A14: WEEK | B14: DATE | C14: SET 1 | E14: SET 2 | G14: SET 3 | I14: SET 4 | K14: TOTAL VOLUMN | L14: NOTES
C15: REP | D15: LOAD | E15: REP | F15: LOAD | G15: REP | H15: LOAD | I15: REP | J15: LOAD
A16: 1 | B16: =B5 | K16: =C16*D16+E16*F16+G16*H16+I16*J16
A17: 2 | B17: =B6 | K17: =C17*D17+E17*F17+G17*H17+I17*J17
A18: 3 | B18: =B7 | K18: =C18*D18+E18*F18+G18*H18+I18*J18
A19: 4 | B19: =B8 | K19: =C19*D19+E19*F19+G19*H19+I19*J19
B20: =B9 | K20: =C20*D20+E20*F20+G20*H20+I20*J20
B21: =B10 | K21: =C21*D21+E21*F21+G21*H21+I21*J21
A23: Exercise | F23: Set | G23: Rep | H23: RIR | I23: Tempo | J23: Rest
A24: ='Training Plan 1'!O7 | F24: ='Training Plan 1'!P7 | G24: ='Training Plan 1'!Q7 | H24: ='Training Plan 1'!R7 | I24: ='Training Plan 1'!S7 | J24: ='Training Plan 1'!T7
A25: WEEK | B25: DATE | C25: SET 1 | E25: SET 2 | G25: SET 3 | I25: SET 4 | K25: TOTAL VOLUMN | L25: NOTES
C26: REP | D26: LOAD | E26: REP | F26: LOAD | G26: REP | H26: LOAD | I26: REP | J26: LOAD
A27: 1 | B27: =B16 | K27: =C27*D27+E27*F27+G27*H27+I27*J27
A28: 2 | B28: =B17 | K28: =C28*D28+E28*F28+G28*H28+I28*J28
A29: 3 | B29: =B18 | K29: =C29*D29+E29*F29+G29*H29+I29*J29
A30: 4 | B30: =B19 | K30: =C30*D30+E30*F30+G30*H30+I30*J30
B31: =B20 | K31: =C31*D31+E31*F31+G31*H31+I31*J31
B32: =B21 | K32: =C32*D32+E32*F32+G32*H32+I32*J32
A34: Exercise | F34: Set | G34: Rep | H34: RIR | I34: Tempo | J34: Rest
A35: ='Training Plan 1'!O8 | F35: ='Training Plan 1'!P8 | G35: ='Training Plan 1'!Q8 | H35: ='Training Plan 1'!R8 | I35: ='Training Plan 1'!S8 | J35: ='Training Plan 1'!T8
A36: WEEK | B36: DATE | C36: SET 1 | E36: SET 2 | G36: SET 3 | I36: SET 4 | K36: TOTAL VOLUMN | L36: NOTES
C37: REP | D37: LOAD | E37: REP | F37: LOAD | G37: REP | H37: LOAD | I37: REP | J37: LOAD
A38: 1 | B38: =B27 | K38: =C38*D38+E38*F38+G38*H38+I38*J38
A39: 2 | B39: =B28 | K39: =C39*D39+E39*F39+G39*H39+I39*J39
A40: 3 | B40: =B29 | K40: =C40*D40+E40*F40+G40*H40+I40*J40
A41: 4 | B41: =B30 | K41: =C41*D41+E41*F41+G41*H41+I41*J41
B42: =B31 | K42: =C42*D42+E42*F42+G42*H42+I42*J42
B43: =B32 | K43: =C43*D43+E43*F43+G43*H43+I43*J43
A45: Exercise | F45: Set | G45: Rep | H45: RIR | I45: Tempo | J45: Rest
A46: ='Training Plan 1'!O9 | F46: ='Training Plan 1'!P9 | G46: ='Training Plan 1'!Q9 | H46: ='Training Plan 1'!R9 | I46: ='Training Plan 1'!S9 | J46: ='Training Plan 1'!T9
A47: WEEK | B47: DATE | C47: SET 1 | E47: SET 2 | G47: SET 3 | I47: SET 4 | K47: TOTAL VOLUMN | L47: NOTES
...

Sheet 1-C
A1: PHASE 1 | C1: WORKOUT 1-C
A3: Session Check-in
A4: WEEK
A5: 1
A6: 2
A7: 3
A8: 4
A12: Exercise | F12: Set | G12: Rep | H12: RIR | I12: Tempo | J12: Rest
A13: ='Training Plan 1'!V6 | F13: ='Training Plan 1'!W6 | G13: ='Training Plan 1'!X6 | H13: ='Training Plan 1'!Y6 | I13: ='Training Plan 1'!Z6 | J13: ='Training Plan 1'!AA6
A14: WEEK | B14: DATE | C14: SET 1 | E14: SET 2 | G14: SET 3 | I14: SET 4 | K14: TOTAL VOLUMN | L14: NOTES
C15: REP | D15: LOAD | E15: REP | F15: LOAD | G15: REP | H15: LOAD | I15: REP | J15: LOAD
A16: 1 | B16: =B5 | K16: =C16*D16+E16*F16+G16*H16+I16*J16
A17: 2 | B17: =B6 | K17: =C17*D17+E17*F17+G17*H17+I17*J17
A18: 3 | B18: =B7 | K18: =C18*D18+E18*F18+G18*H18+I18*J18
A19: 4 | B19: =B8 | K19: =C19*D19+E19*F19+G19*H19+I19*J19
B20: =B9 | K20: =C20*D20+E20*F20+G20*H20+I20*J20
B21: =B10 | K21: =C21*D21+E21*F21+G21*H21+I21*J21
A23: Exercise | F23: Set | G23: Rep | H23: RIR | I23: Tempo | J23: Rest
A24: ='Training Plan 1'!V7 | F24: ='Training Plan 1'!W7 | G24: ='Training Plan 1'!X7 | H24: ='Training Plan 1'!Y7 | I24: ='Training Plan 1'!Z7 | J24: ='Training Plan 1'!AA7
A25: WEEK | B25: DATE | C25: SET 1 | E25: SET 2 | G25: SET 3 | I25: SET 4 | K25: TOTAL VOLUMN | L25: NOTES
C26: REP | D26: LOAD | E26: REP | F26: LOAD | G26: REP | H26: LOAD | I26: REP | J26: LOAD
A27: 1 | B27: =B16 | K27: =C27*D27+E27*F27+G27*H27+I27*J27
A28: 2 | B28: =B17 | K28: =C28*D28+E28*F28+G28*H28+I28*J28
A29: 3 | B29: =B18 | K29: =C29*D29+E29*F29+G29*H29+I29*J29
A30: 4 | B30: =B19 | K30: =C30*D30+E30*F30+G30*H30+I30*J30
B31: =B20 | K31: =C31*D31+E31*F31+G31*H31+I31*J31
B32: =B21 | K32: =C32*D32+E32*F32+G32*H32+I32*J32
A34: Exercise | F34: Set | G34: Rep | H34: RIR | I34: Tempo | J34: Rest
A35: ='Training Plan 1'!V8 | F35: ='Training Plan 1'!W8 | G35: ='Training Plan 1'!X8 | H35: ='Training Plan 1'!Y8 | I35: ='Training Plan 1'!Z8 | J35: ='Training Plan 1'!AA8
A36: WEEK | B36: DATE | C36: SET 1 | E36: SET 2 | G36: SET 3 | I36: SET 4 | K36: TOTAL VOLUMN | L36: NOTES
C37: REP | D37: LOAD | E37: REP | F37: LOAD | G37: REP | H37: LOAD | I37: REP | J37: LOAD
A38: 1 | B38: =B27 | K38: =C38*D38+E38*F38+G38*H38+I38*J38
A39: 2 | B39: =B28 | K39: =C39*D39+E39*F39+G39*H39+I39*J39
A40: 3 | B40: =B29 | K40: =C40*D40+E40*F40+G40*H40+I40*J40
A41: 4 | B41: =B30 | K41: =C41*D41+E41*F41+G41*H41+I41*J41
B42: =B31 | K42: =C42*D42+E42*F42+G42*H42+I42*J42
B43: =B32 | K43: =C43*D43+E43*F43+G43*H43+I43*J43
A45: Exercise | F45: Set | G45: Rep | H45: RIR | I45: Tempo | J45: Rest
A46: ='Training Plan 1'!V9 | F46: ='Training Plan 1'!W9 | G46: ='Training Plan 1'!X9 | H46: ='Training Plan 1'!Y9 | I46: ='Training Plan 1'!Z9 | J46: ='Training Plan 1'!AA9
A47: WEEK | B47: DATE | C47: SET 1 | E47: SET 2 | G47: SET 3 | I47: SET 4 | K47: TOTAL VOLUMN | L47: NOTES
...

Sheet 1-D
A1: PHASE 1 | C1: WORKOUT 1-D
A3: Session Check-in
A4: WEEK
A5: 1
A6: 2
A7: 3
A8: 4
A12: Exercise | F12: Set | G12: Rep | H12: RIR | I12: Tempo | J12: Rest
A13: ='Training Plan 1'!AC6 | F13: ='Training Plan 1'!AD6 | G13: ='Training Plan 1'!AE6 | H13: ='Training Plan 1'!AF6 | I13: ='Training Plan 1'!AG6 | J13: ='Training Plan 1'!AH6
A14: WEEK | B14: DATE | C14: SET 1 | E14: SET 2 | G14: SET 3 | I14: SET 4 | K14: TOTAL VOLUMN | L14: NOTES
C15: REP | D15: LOAD | E15: REP | F15: LOAD | G15: REP | H15: LOAD | I15: REP | J15: LOAD
A16: 1 | B16: =B5 | K16: =C16*D16+E16*F16+G16*H16+I16*J16
A17: 2 | B17: =B6 | K17: =C17*D17+E17*F17+G17*H17+I17*J17
A18: 3 | B18: =B7 | K18: =C18*D18+E18*F18+G18*H18+I18*J18
A19: 4 | B19: =B8 | K19: =C19*D19+E19*F19+G19*H19+I19*J19
B20: =B9 | K20: =C20*D20+E20*F20+G20*H20+I20*J20
B21: =B10 | K21: =C21*D21+E21*F21+G21*H21+I21*J21
A23: Exercise | F23: Set | G23: Rep | H23: RIR | I23: Tempo | J23: Rest
A24: ='Training Plan 1'!AC7 | F24: ='Training Plan 1'!AD7 | G24: ='Training Plan 1'!AE7 | H24: ='Training Plan 1'!AF7 | I24: ='Training Plan 1'!AG7 | J24: ='Training Plan 1'!AH7
A25: WEEK | B25: DATE | C25: SET 1 | E25: SET 2 | G25: SET 3 | I25: SET 4 | K25: TOTAL VOLUMN | L25: NOTES
C26: REP | D26: LOAD | E26: REP | F26: LOAD | G26: REP | H26: LOAD | I26: REP | J26: LOAD
A27: 1 | B27: =B16 | K27: =C27*D27+E27*F27+G27*H27+I27*J27
A28: 2 | B28: =B17 | K28: =C28*D28+E28*F28+G28*H28+I28*J28
A29: 3 | B29: =B18 | K29: =C29*D29+E29*F29+G29*H29+I29*J29
A30: 4 | B30: =B19 | K30: =C30*D30+E30*F30+G30*H30+I30*J30
B31: =B20 | K31: =C31*D31+E31*F31+G31*H31+I31*J31
B32: =B21 | K32: =C32*D32+E32*F32+G32*H32+I32*J32
A34: Exercise | F34: Set | G34: Rep | H34: RIR | I34: Tempo | J34: Rest
A35: ='Training Plan 1'!AC8 | F35: ='Training Plan 1'!AD8 | G35: ='Training Plan 1'!AE8 | H35: ='Training Plan 1'!AF8 | I35: ='Training Plan 1'!AG8 | J35: ='Training Plan 1'!AH8
A36: WEEK | B36: DATE | C36: SET 1 | E36: SET 2 | G36: SET 3 | I36: SET 4 | K36: TOTAL VOLUMN | L36: NOTES
C37: REP | D37: LOAD | E37: REP | F37: LOAD | G37: REP | H37: LOAD | I37: REP | J37: LOAD
A38: 1 | B38: =B27 | K38: =C38*D38+E38*F38+G38*H38+I38*J38
A39: 2 | B39: =B28 | K39: =C39*D39+E39*F39+G39*H39+I39*J39
A40: 3 | B40: =B29 | K40: =C40*D40+E40*F40+G40*H40+I40*J40
A41: 4 | B41: =B30 | K41: =C41*D41+E41*F41+G41*H41+I41*J41
B42: =B31 | K42: =C42*D42+E42*F42+G42*H42+I42*J42
B43: =B32 | K43: =C43*D43+E43*F43+G43*H43+I43*J43
A45: Exercise | F45: Set | G45: Rep | H45: RIR | I45: Tempo | J45: Rest
A46: ='Training Plan 1'!AC9 | F46: ='Training Plan 1'!AD9 | G46: ='Training Plan 1'!AE9 | H46: ='Training Plan 1'!AF9 | I46: ='Training Plan 1'!AG9 | J46: ='Training Plan 1'!AH9
A47: WEEK | B47: DATE | C47: SET 1 | E47: SET 2 | G47: SET 3 | I47: SET 4 | K47: TOTAL VOLUMN | L47: NOTES
...

Sheet 2-A
A1: PHASE 1 | C1: WORKOUT 2-A
A3: Session Check-in
A4: WEEK
A5: 1
A6: 2
A7: 3
A8: 4
A12: Exercise | F12: Set | G12: Rep | H12: RIR | I12: Tempo | J12: Rest
A13: ='Training Plan 1'!H16 | F13: ='Training Plan 1'!I16 | G13: ='Training Plan 1'!J16 | H13: ='Training Plan 1'!K16 | I13: ='Training Plan 1'!L16 | J13: ='Training Plan 1'!M16
A14: WEEK | B14: DATE | C14: SET 1 | E14: SET 2 | G14: SET 3 | I14: SET 4 | K14: TOTAL VOLUMN | L14: NOTES
C15: REP | D15: LOAD | E15: REP | F15: LOAD | G15: REP | H15: LOAD | I15: REP | J15: LOAD
A16: 1 | B16: =B5 | K16: =C16*D16+E16*F16+G16*H16+I16*J16
A17: 2 | B17: =B6 | K17: =C17*D17+E17*F17+G17*H17+I17*J17
A18: 3 | B18: =B7 | K18: =C18*D18+E18*F18+G18*H18+I18*J18
A19: 4 | B19: =B8 | K19: =C19*D19+E19*F19+G19*H19+I19*J19
B20: =B9
B21: =B10
A23: Exercise | F23: Set | G23: Rep | H23: RIR | I23: Tempo | J23: Rest
A24: ='Training Plan 1'!H17 | F24: ='Training Plan 1'!I17 | G24: ='Training Plan 1'!J17 | H24: ='Training Plan 1'!K17 | I24: ='Training Plan 1'!L17 | J24: ='Training Plan 1'!M17
A25: WEEK | B25: DATE | C25: SET 1 | E25: SET 2 | G25: SET 3 | I25: SET 4 | K25: TOTAL VOLUMN | L25: NOTES
C26: REP | D26: LOAD | E26: REP | F26: LOAD | G26: REP | H26: LOAD | I26: REP | J26: LOAD
A27: 1 | B27: =B16 | K27: =C27*D27+E27*F27+G27*H27+I27*J27
A28: 2 | B28: =B17 | K28: =C28*D28+E28*F28+G28*H28+I28*J28
A29: 3 | B29: =B18 | K29: =C29*D29+E29*F29+G29*H29+I29*J29
A30: 4 | B30: =B19 | K30: =C30*D30+E30*F30+G30*H30+I30*J30
B31: =B20
B32: =B21
A34: Exercise | F34: Set | G34: Rep | H34: RIR | I34: Tempo | J34: Rest
A35: ='Training Plan 1'!H18 | F35: ='Training Plan 1'!I18 | G35: ='Training Plan 1'!J18 | H35: ='Training Plan 1'!K18 | I35: ='Training Plan 1'!L18 | J35: ='Training Plan 1'!M18
A36: WEEK | B36: DATE | C36: SET 1 | E36: SET 2 | G36: SET 3 | I36: SET 4 | K36: TOTAL VOLUMN | L36: NOTES
C37: REP | D37: LOAD | E37: REP | F37: LOAD | G37: REP | H37: LOAD | I37: REP | J37: LOAD
A38: 1 | B38: =B27 | K38: =C38*D38+E38*F38+G38*H38+I38*J38
A39: 2 | B39: =B28 | K39: =C39*D39+E39*F39+G39*H39+I39*J39
A40: 3 | B40: =B29 | K40: =C40*D40+E40*F40+G40*H40+I40*J40
A41: 4 | B41: =B30 | K41: =C41*D41+E41*F41+G41*H41+I41*J41
B42: =B31
B43: =B32
A45: Exercise | F45: Set | G45: Rep | H45: RIR | I45: Tempo | J45: Rest
A46: ='Training Plan 1'!H19 | F46: ='Training Plan 1'!I19 | G46: ='Training Plan 1'!J19 | H46: ='Training Plan 1'!K19 | I46: ='Training Plan 1'!L19 | J46: ='Training Plan 1'!M19
A47: WEEK | B47: DATE | C47: SET 1 | E47: SET 2 | G47: SET 3 | I47: SET 4 | K47: TOTAL VOLUMN | L47: NOTES
...

Sheet 2-B
A1: PHASE 1 | C1: WORKOUT 2-B
A3: Session Check-in
A4: WEEK
A5: 1
A6: 2
A7: 3
A8: 4
A12: Exercise | F12: Set | G12: Rep | H12: RIR | I12: Tempo | J12: Rest
A13: ='Training Plan 1'!O16 | F13: ='Training Plan 1'!P16 | G13: ='Training Plan 1'!Q16 | H13: ='Training Plan 1'!R16 | I13: ='Training Plan 1'!S16 | J13: ='Training Plan 1'!T16
A14: WEEK | B14: DATE | C14: SET 1 | E14: SET 2 | G14: SET 3 | I14: SET 4 | K14: TOTAL VOLUMN | L14: NOTES
C15: REP | D15: LOAD | E15: REP | F15: LOAD | G15: REP | H15: LOAD | I15: REP | J15: LOAD
A16: 1 | B16: =B5 | K16: =C16*D16+E16*F16+G16*H16+I16*J16
A17: 2 | B17: =B6 | K17: =C17*D17+E17*F17+G17*H17+I17*J17
A18: 3 | B18: =B7 | K18: =C18*D18+E18*F18+G18*H18+I18*J18
A19: 4 | B19: =B8 | K19: =C19*D19+E19*F19+G19*H19+I19*J19
B20: =B9
B21: =B10
A23: Exercise | F23: Set | G23: Rep | H23: RIR | I23: Tempo | J23: Rest
A24: ='Training Plan 1'!O17 | F24: ='Training Plan 1'!P17 | G24: ='Training Plan 1'!Q17 | H24: ='Training Plan 1'!R17 | I24: ='Training Plan 1'!S17 | J24: ='Training Plan 1'!T17
A25: WEEK | B25: DATE | C25: SET 1 | E25: SET 2 | G25: SET 3 | I25: SET 4 | K25: TOTAL VOLUMN | L25: NOTES
C26: REP | D26: LOAD | E26: REP | F26: LOAD | G26: REP | H26: LOAD | I26: REP | J26: LOAD
A27: 1 | B27: =B16 | K27: =C27*D27+E27*F27+G27*H27+I27*J27
A28: 2 | B28: =B17 | K28: =C28*D28+E28*F28+G28*H28+I28*J28
A29: 3 | B29: =B18 | K29: =C29*D29+E29*F29+G29*H29+I29*J29
A30: 4 | B30: =B19 | K30: =C30*D30+E30*F30+G30*H30+I30*J30
B31: =B20
B32: =B21
A34: Exercise | F34: Set | G34: Rep | H34: RIR | I34: Tempo | J34: Rest
A35: ='Training Plan 1'!O18 | F35: ='Training Plan 1'!P18 | G35: ='Training Plan 1'!Q18 | H35: ='Training Plan 1'!R18 | I35: ='Training Plan 1'!S18 | J35: ='Training Plan 1'!T18
A36: WEEK | B36: DATE | C36: SET 1 | E36: SET 2 | G36: SET 3 | I36: SET 4 | K36: TOTAL VOLUMN | L36: NOTES
C37: REP | D37: LOAD | E37: REP | F37: LOAD | G37: REP | H37: LOAD | I37: REP | J37: LOAD
A38: 1 | B38: =B27 | K38: =C38*D38+E38*F38+G38*H38+I38*J38
A39: 2 | B39: =B28 | K39: =C39*D39+E39*F39+G39*H39+I39*J39
A40: 3 | B40: =B29 | K40: =C40*D40+E40*F40+G40*H40+I40*J40
A41: 4 | B41: =B30 | K41: =C41*D41+E41*F41+G41*H41+I41*J41
B42: =B31
B43: =B32
A45: Exercise | F45: Set | G45: Rep | H45: RIR | I45: Tempo | J45: Rest
A46: ='Training Plan 1'!O19 | F46: ='Training Plan 1'!P19 | G46: ='Training Plan 1'!Q19 | H46: ='Training Plan 1'!R19 | I46: ='Training Plan 1'!S19 | J46: ='Training Plan 1'!T19
A47: WEEK | B47: DATE | C47: SET 1 | E47: SET 2 | G47: SET 3 | I47: SET 4 | K47: TOTAL VOLUMN | L47: NOTES
...

Sheet 2-C
A1: PHASE 1 | C1: WORKOUT 2-C
A3: Session Check-in
A4: WEEK
A5: 1
A6: 2
A7: 3
A8: 4
A12: Exercise | F12: Set | G12: Rep | H12: RIR | I12: Tempo | J12: Rest
A13: ='Training Plan 1'!V16 | F13: ='Training Plan 1'!W16 | G13: ='Training Plan 1'!X16 | H13: ='Training Plan 1'!Y16 | I13: ='Training Plan 1'!Z16 | J13: ='Training Plan 1'!AA16
A14: WEEK | B14: DATE | C14: SET 1 | E14: SET 2 | G14: SET 3 | I14: SET 4 | K14: TOTAL VOLUMN | L14: NOTES
C15: REP | D15: LOAD | E15: REP | F15: LOAD | G15: REP | H15: LOAD | I15: REP | J15: LOAD
A16: 1 | B16: =B5 | K16: =C16*D16+E16*F16+G16*H16+I16*J16
A17: 2 | B17: =B6 | K17: =C17*D17+E17*F17+G17*H17+I17*J17
A18: 3 | B18: =B7 | K18: =C18*D18+E18*F18+G18*H18+I18*J18
A19: 4 | B19: =B8 | K19: =C19*D19+E19*F19+G19*H19+I19*J19
B20: =B9
B21: =B10
A23: Exercise | F23: Set | G23: Rep | H23: RIR | I23: Tempo | J23: Rest
A24: ='Training Plan 1'!V17 | F24: ='Training Plan 1'!W17 | G24: ='Training Plan 1'!X17 | H24: ='Training Plan 1'!Y17 | I24: ='Training Plan 1'!Z17 | J24: ='Training Plan 1'!AA17
A25: WEEK | B25: DATE | C25: SET 1 | E25: SET 2 | G25: SET 3 | I25: SET 4 | K25: TOTAL VOLUMN | L25: NOTES
C26: REP | D26: LOAD | E26: REP | F26: LOAD | G26: REP | H26: LOAD | I26: REP | J26: LOAD
A27: 1 | B27: =B16 | K27: =C27*D27+E27*F27+G27*H27+I27*J27
A28: 2 | B28: =B17 | K28: =C28*D28+E28*F28+G28*H28+I28*J28
A29: 3 | B29: =B18 | K29: =C29*D29+E29*F29+G29*H29+I29*J29
A30: 4 | B30: =B19 | K30: =C30*D30+E30*F30+G30*H30+I30*J30
B31: =B20
B32: =B21
A34: Exercise | F34: Set | G34: Rep | H34: RIR | I34: Tempo | J34: Rest
A35: ='Training Plan 1'!V18 | F35: ='Training Plan 1'!W18 | G35: ='Training Plan 1'!X18 | H35: ='Training Plan 1'!Y18 | I35: ='Training Plan 1'!Z18 | J35: ='Training Plan 1'!AA18
A36: WEEK | B36: DATE | C36: SET 1 | E36: SET 2 | G36: SET 3 | I36: SET 4 | K36: TOTAL VOLUMN | L36: NOTES
C37: REP | D37: LOAD | E37: REP | F37: LOAD | G37: REP | H37: LOAD | I37: REP | J37: LOAD
A38: 1 | B38: =B27 | K38: =C38*D38+E38*F38+G38*H38+I38*J38
A39: 2 | B39: =B28 | K39: =C39*D39+E39*F39+G39*H39+I39*J39
A40: 3 | B40: =B29 | K40: =C40*D40+E40*F40+G40*H40+I40*J40
A41: 4 | B41: =B30 | K41: =C41*D41+E41*F41+G41*H41+I41*J41
B42: =B31
B43: =B32
A45: Exercise | F45: Set | G45: Rep | H45: RIR | I45: Tempo | J45: Rest
A46: ='Training Plan 1'!V19 | F46: ='Training Plan 1'!W19 | G46: ='Training Plan 1'!X19 | H46: ='Training Plan 1'!Y19 | I46: ='Training Plan 1'!Z19 | J46: ='Training Plan 1'!AA19
A47: WEEK | B47: DATE | C47: SET 1 | E47: SET 2 | G47: SET 3 | I47: SET 4 | K47: TOTAL VOLUMN | L47: NOTES
...

Sheet 2-D
A1: PHASE 1 | C1: WORKOUT 2-D
A3: Session Check-in
A4: WEEK
A5: 1
A6: 2
A7: 3
A8: 4
A12: Exercise | F12: Set | G12: Rep | H12: RIR | I12: Tempo | J12: Rest
A13: ='Training Plan 1'!AC16 | F13: ='Training Plan 1'!AD16 | G13: ='Training Plan 1'!AE16 | H13: ='Training Plan 1'!AF16 | I13: ='Training Plan 1'!AG16 | J13: ='Training Plan 1'!AH16
A14: WEEK | B14: DATE | C14: SET 1 | E14: SET 2 | G14: SET 3 | I14: SET 4 | K14: TOTAL VOLUMN | L14: NOTES
C15: REP | D15: LOAD | E15: REP | F15: LOAD | G15: REP | H15: LOAD | I15: REP | J15: LOAD
A16: 1 | B16: =B5 | K16: =C16*D16+E16*F16+G16*H16+I16*J16
A17: 2 | B17: =B6 | K17: =C17*D17+E17*F17+G17*H17+I17*J17
A18: 3 | B18: =B7 | K18: =C18*D18+E18*F18+G18*H18+I18*J18
A19: 4 | B19: =B8 | K19: =C19*D19+E19*F19+G19*H19+I19*J19
B20: =B9
B21: =B10
A23: Exercise | F23: Set | G23: Rep | H23: RIR | I23: Tempo | J23: Rest
A24: ='Training Plan 1'!AC17 | F24: ='Training Plan 1'!AD17 | G24: ='Training Plan 1'!AE17 | H24: ='Training Plan 1'!AF17 | I24: ='Training Plan 1'!AG17 | J24: ='Training Plan 1'!AH17
A25: WEEK | B25: DATE | C25: SET 1 | E25: SET 2 | G25: SET 3 | I25: SET 4 | K25: TOTAL VOLUMN | L25: NOTES
C26: REP | D26: LOAD | E26: REP | F26: LOAD | G26: REP | H26: LOAD | I26: REP | J26: LOAD
A27: 1 | B27: =B16 | K27: =C27*D27+E27*F27+G27*H27+I27*J27
A28: 2 | B28: =B17 | K28: =C28*D28+E28*F28+G28*H28+I28*J28
A29: 3 | B29: =B18 | K29: =C29*D29+E29*F29+G29*H29+I29*J29
A30: 4 | B30: =B19 | K30: =C30*D30+E30*F30+G30*H30+I30*J30
B31: =B20
B32: =B21
A34: Exercise | F34: Set | G34: Rep | H34: RIR | I34: Tempo | J34: Rest
A35: ='Training Plan 1'!AD18 | F35: ='Training Plan 1'!AD18 | G35: ='Training Plan 1'!AE18 | H35: ='Training Plan 1'!AF18 | I35: ='Training Plan 1'!AG18 | J35: ='Training Plan 1'!AH18
A36: WEEK | B36: DATE | C36: SET 1 | E36: SET 2 | G36: SET 3 | I36: SET 4 | K36: TOTAL VOLUMN | L36: NOTES
C37: REP | D37: LOAD | E37: REP | F37: LOAD | G37: REP | H37: LOAD | I37: REP | J37: LOAD
A38: 1 | B38: =B27 | K38: =C38*D38+E38*F38+G38*H38+I38*J38
A39: 2 | B39: =B28 | K39: =C39*D39+E39*F39+G39*H39+I39*J39
A40: 3 | B40: =B29 | K40: =C40*D40+E40*F40+G40*H40+I40*J40
A41: 4 | B41: =B30 | K41: =C41*D41+E41*F41+G41*H41+I41*J41
B42: =B31
B43: =B32
A45: Exercise | F45: Set | G45: Rep | H45: RIR | I45: Tempo | J45: Rest
A46: ='Training Plan 1'!AC19 | F46: ='Training Plan 1'!AD19 | G46: ='Training Plan 1'!AE19 | H46: ='Training Plan 1'!AF19 | I46: ='Training Plan 1'!AG19 | J46: ='Training Plan 1'!AH19
A47: WEEK | B47: DATE | C47: SET 1 | E47: SET 2 | G47: SET 3 | I47: SET 4 | K47: TOTAL VOLUMN | L47: NOTES
...

Sheet 3-A
A1: PHASE 1 | C1: WORKOUT 3-A
A3: Session Check-in
A4: WEEK
A5: 1
A6: 2
A7: 3
A8: 4
A12: Exercise | F12: Set | G12: Rep | H12: RIR | I12: Tempo | J12: Rest
A13: ='Training Plan 1'!H26 | F13: ='Training Plan 1'!I26 | G13: ='Training Plan 1'!J26 | H13: ='Training Plan 1'!K26 | I13: ='Training Plan 1'!L26 | J13: ='Training Plan 1'!M26
A14: WEEK | B14: DATE | C14: SET 1 | E14: SET 2 | G14: SET 3 | I14: SET 4 | K14: TOTAL VOLUMN | L14: NOTES
C15: REP | D15: LOAD | E15: REP | F15: LOAD | G15: REP | H15: LOAD | I15: REP | J15: LOAD
A16: 1 | B16: =B5 | K16: =C16*D16+E16*F16+G16*H16+I16*J16
A17: 2 | B17: =B6 | K17: =C17*D17+E17*F17+G17*H17+I17*J17
A18: 3 | B18: =B7 | K18: =C18*D18+E18*F18+G18*H18+I18*J18
A19: 4 | B19: =B8 | K19: =C19*D19+E19*F19+G19*H19+I19*J19
B20: =B9
B21: =B10
A23: Exercise | F23: Set | G23: Rep | H23: RIR | I23: Tempo | J23: Rest
A24: ='Training Plan 1'!H27 | F24: ='Training Plan 1'!I27 | G24: ='Training Plan 1'!J27 | H24: ='Training Plan 1'!K27 | I24: ='Training Plan 1'!L27 | J24: ='Training Plan 1'!M27
A25: WEEK | B25: DATE | C25: SET 1 | E25: SET 2 | G25: SET 3 | I25: SET 4 | K25: TOTAL VOLUMN | L25: NOTES
C26: REP | D26: LOAD | E26: REP | F26: LOAD | G26: REP | H26: LOAD | I26: REP | J26: LOAD
A27: 1 | B27: =B16 | K27: =C27*D27+E27*F27+G27*H27+I27*J27
A28: 2 | B28: =B17 | K28: =C28*D28+E28*F28+G28*H28+I28*J28
A29: 3 | B29: =B18 | K29: =C29*D29+E29*F29+G29*H29+I29*J29
A30: 4 | B30: =B19 | K30: =C30*D30+E30*F30+G30*H30+I30*J30
B31: =B20
B32: =B21
A34: Exercise | F34: Set | G34: Rep | H34: RIR | I34: Tempo | J34: Rest
A35: ='Training Plan 1'!H28 | F35: ='Training Plan 1'!I28 | G35: ='Training Plan 1'!J28 | H35: ='Training Plan 1'!K28 | I35: ='Training Plan 1'!L28 | J35: ='Training Plan 1'!M28
A36: WEEK | B36: DATE | C36: SET 1 | E36: SET 2 | G36: SET 3 | I36: SET 4 | K36: TOTAL VOLUMN | L36: NOTES
C37: REP | D37: LOAD | E37: REP | F37: LOAD | G37: REP | H37: LOAD | I37: REP | J37: LOAD
A38: 1 | B38: =B27 | K38: =C38*D38+E38*F38+G38*H38+I38*J38
A39: 2 | B39: =B28 | K39: =C39*D39+E39*F39+G39*H39+I39*J39
A40: 3 | B40: =B29 | K40: =C40*D40+E40*F40+G40*H40+I40*J40
A41: 4 | B41: =B30 | K41: =C41*D41+E41*F41+G41*H41+I41*J41
B42: =B31
B43: =B32
A45: Exercise | F45: Set | G45: Rep | H45: RIR | I45: Tempo | J45: Rest
A46: ='Training Plan 1'!H29 | F46: ='Training Plan 1'!I29 | G46: ='Training Plan 1'!J29 | H46: ='Training Plan 1'!K29 | I46: ='Training Plan 1'!L29 | J46: ='Training Plan 1'!M29
A47: WEEK | B47: DATE | C47: SET 1 | E47: SET 2 | G47: SET 3 | I47: SET 4 | K47: TOTAL VOLUMN | L47: NOTES
...

Sheet 3-B
A1: PHASE 1 | C1: WORKOUT 3-B
A3: Session Check-in
A4: WEEK
A5: 1
A6: 2
A7: 3
A8: 4
A12: Exercise | F12: Set | G12: Rep | H12: RIR | I12: Tempo | J12: Rest
A13: ='Training Plan 1'!O26 | F13: ='Training Plan 1'!P26 | G13: ='Training Plan 1'!Q26 | H13: ='Training Plan 1'!R26 | I13: ='Training Plan 1'!S26 | J13: ='Training Plan 1'!T26
A14: WEEK | B14: DATE | C14: SET 1 | E14: SET 2 | G14: SET 3 | I14: SET 4 | K14: TOTAL VOLUMN | L14: NOTES
C15: REP | D15: LOAD | E15: REP | F15: LOAD | G15: REP | H15: LOAD | I15: REP | J15: LOAD
A16: 1 | B16: =B5 | K16: =C16*D16+E16*F16+G16*H16+I16*J16
A17: 2 | B17: =B6 | K17: =C17*D17+E17*F17+G17*H17+I17*J17
A18: 3 | B18: =B7 | K18: =C18*D18+E18*F18+G18*H18+I18*J18
A19: 4 | B19: =B8 | K19: =C19*D19+E19*F19+G19*H19+I19*J19
B20: =B9
B21: =B10
A23: Exercise | F23: Set | G23: Rep | H23: RIR | I23: Tempo | J23: Rest
A24: ='Training Plan 1'!O27 | F24: ='Training Plan 1'!P27 | G24: ='Training Plan 1'!Q27 | H24: ='Training Plan 1'!R27 | I24: ='Training Plan 1'!S27 | J24: ='Training Plan 1'!T27
A25: WEEK | B25: DATE | C25: SET 1 | E25: SET 2 | G25: SET 3 | I25: SET 4 | K25: TOTAL VOLUMN | L25: NOTES
C26: REP | D26: LOAD | E26: REP | F26: LOAD | G26: REP | H26: LOAD | I26: REP | J26: LOAD
A27: 1 | B27: =B16 | K27: =C27*D27+E27*F27+G27*H27+I27*J27
A28: 2 | B28: =B17 | K28: =C28*D28+E28*F28+G28*H28+I28*J28
A29: 3 | B29: =B18 | K29: =C29*D29+E29*F29+G29*H29+I29*J29
A30: 4 | B30: =B19 | K30: =C30*D30+E30*F30+G30*H30+I30*J30
B31: =B20
B32: =B21
A34: Exercise | F34: Set | G34: Rep | H34: RIR | I34: Tempo | J34: Rest
A35: ='Training Plan 1'!O28 | F35: ='Training Plan 1'!P28 | G35: ='Training Plan 1'!Q28 | H35: ='Training Plan 1'!R28 | I35: ='Training Plan 1'!S28 | J35: ='Training Plan 1'!T28
A36: WEEK | B36: DATE | C36: SET 1 | E36: SET 2 | G36: SET 3 | I36: SET 4 | K36: TOTAL VOLUMN | L36: NOTES
C37: REP | D37: LOAD | E37: REP | F37: LOAD | G37: REP | H37: LOAD | I37: REP | J37: LOAD
A38: 1 | B38: =B27 | K38: =C38*D38+E38*F38+G38*H38+I38*J38
A39: 2 | B39: =B28 | K39: =C39*D39+E39*F39+G39*H39+I39*J39
A40: 3 | B40: =B29 | K40: =C40*D40+E40*F40+G40*H40+I40*J40
A41: 4 | B41: =B30 | K41: =C41*D41+E41*F41+G41*H41+I41*J41
B42: =B31
B43: =B32
A45: Exercise | F45: Set | G45: Rep | H45: RIR | I45: Tempo | J45: Rest
A46: ='Training Plan 1'!O29 | F46: ='Training Plan 1'!P29 | G46: ='Training Plan 1'!Q29 | H46: ='Training Plan 1'!R29 | I46: ='Training Plan 1'!S29 | J46: ='Training Plan 1'!T29
A47: WEEK | B47: DATE | C47: SET 1 | E47: SET 2 | G47: SET 3 | I47: SET 4 | K47: TOTAL VOLUMN | L47: NOTES
...

Sheet 3-C
A1: PHASE 1 | C1: WORKOUT 3-C
A3: Session Check-in
A4: WEEK
A5: 1
A6: 2
A7: 3
A8: 4
A12: Exercise | F12: Set | G12: Rep | H12: RIR | I12: Tempo | J12: Rest
A13: ='Training Plan 1'!V26 | F13: ='Training Plan 1'!W26 | G13: ='Training Plan 1'!X26 | H13: ='Training Plan 1'!Y26 | I13: ='Training Plan 1'!Z26 | J13: ='Training Plan 1'!AA26
A14: WEEK | B14: DATE | C14: SET 1 | E14: SET 2 | G14: SET 3 | I14: SET 4 | K14: TOTAL VOLUMN | L14: NOTES
C15: REP | D15: LOAD | E15: REP | F15: LOAD | G15: REP | H15: LOAD | I15: REP | J15: LOAD
A16: 1 | B16: =B5 | K16: =C16*D16+E16*F16+G16*H16+I16*J16
A17: 2 | B17: =B6 | K17: =C17*D17+E17*F17+G17*H17+I17*J17
A18: 3 | B18: =B7 | K18: =C18*D18+E18*F18+G18*H18+I18*J18
A19: 4 | B19: =B8 | K19: =C19*D19+E19*F19+G19*H19+I19*J19
B20: =B9
B21: =B10
A23: Exercise | F23: Set | G23: Rep | H23: RIR | I23: Tempo | J23: Rest
A24: ='Training Plan 1'!V27 | F24: ='Training Plan 1'!W27 | G24: ='Training Plan 1'!X27 | H24: ='Training Plan 1'!Y27 | I24: ='Training Plan 1'!Z27 | J24: ='Training Plan 1'!AA27
A25: WEEK | B25: DATE | C25: SET 1 | E25: SET 2 | G25: SET 3 | I25: SET 4 | K25: TOTAL VOLUMN | L25: NOTES
C26: REP | D26: LOAD | E26: REP | F26: LOAD | G26: REP | H26: LOAD | I26: REP | J26: LOAD
A27: 1 | B27: =B16 | K27: =C27*D27+E27*F27+G27*H27+I27*J27
A28: 2 | B28: =B17 | K28: =C28*D28+E28*F28+G28*H28+I28*J28
A29: 3 | B29: =B18 | K29: =C29*D29+E29*F29+G29*H29+I29*J29
A30: 4 | B30: =B19 | K30: =C30*D30+E30*F30+G30*H30+I30*J30
B31: =B20
B32: =B21
A34: Exercise | F34: Set | G34: Rep | H34: RIR | I34: Tempo | J34: Rest
A35: ='Training Plan 1'!V28 | F35: ='Training Plan 1'!W28 | G35: ='Training Plan 1'!X28 | H35: ='Training Plan 1'!Y28 | I35: ='Training Plan 1'!Z28 | J35: ='Training Plan 1'!AA28
A36: WEEK | B36: DATE | C36: SET 1 | E36: SET 2 | G36: SET 3 | I36: SET 4 | K36: TOTAL VOLUMN | L36: NOTES
C37: REP | D37: LOAD | E37: REP | F37: LOAD | G37: REP | H37: LOAD | I37: REP | J37: LOAD
A38: 1 | B38: =B27 | K38: =C38*D38+E38*F38+G38*H38+I38*J38
A39: 2 | B39: =B28 | K39: =C39*D39+E39*F39+G39*H39+I39*J39
A40: 3 | B40: =B29 | K40: =C40*D40+E40*F40+G40*H40+I40*J40
A41: 4 | B41: =B30 | K41: =C41*D41+E41*F41+G41*H41+I41*J41
B42: =B31
B43: =B32
A45: Exercise | F45: Set | G45: Rep | H45: RIR | I45: Tempo | J45: Rest
A46: ='Training Plan 1'!V29 | F46: ='Training Plan 1'!W29 | G46: ='Training Plan 1'!X29 | H46: ='Training Plan 1'!Y29 | I46: ='Training Plan 1'!Z29 | J46: ='Training Plan 1'!AA29
A47: WEEK | B47: DATE | C47: SET 1 | E47: SET 2 | G47: SET 3 | I47: SET 4 | K47: TOTAL VOLUMN | L47: NOTES
...

Sheet 3-D
A1: PHASE 1 | C1: WORKOUT 3-D
A3: Session Check-in
A4: WEEK
A5: 1
A6: 2
A7: 3
A8: 4
A12: Exercise | F12: Set | G12: Rep | H12: RIR | I12: Tempo | J12: Rest
A13: ='Training Plan 1'!AC26 | F13: ='Training Plan 1'!AD26 | G13: ='Training Plan 1'!AE26 | H13: ='Training Plan 1'!AF26 | I13: ='Training Plan 1'!AG26 | J13: ='Training Plan 1'!AH26
A14: WEEK | B14: DATE | C14: SET 1 | E14: SET 2 | G14: SET 3 | I14: SET 4 | K14: TOTAL VOLUMN | L14: NOTES
C15: REP | D15: LOAD | E15: REP | F15: LOAD | G15: REP | H15: LOAD | I15: REP | J15: LOAD
A16: 1 | B16: =B5 | K16: =C16*D16+E16*F16+G16*H16+I16*J16
A17: 2 | B17: =B6 | K17: =C17*D17+E17*F17+G17*H17+I17*J17
A18: 3 | B18: =B7 | K18: =C18*D18+E18*F18+G18*H18+I18*J18
A19: 4 | B19: =B8 | K19: =C19*D19+E19*F19+G19*H19+I19*J19
B20: =B9
B21: =B10
A23: Exercise | F23: Set | G23: Rep | H23: RIR | I23: Tempo | J23: Rest
A24: ='Training Plan 1'!AC27 | F24: ='Training Plan 1'!AD27 | G24: ='Training Plan 1'!AE27 | H24: ='Training Plan 1'!AF27 | I24: ='Training Plan 1'!AG27 | J24: ='Training Plan 1'!AH27
A25: WEEK | B25: DATE | C25: SET 1 | E25: SET 2 | G25: SET 3 | I25: SET 4 | K25: TOTAL VOLUMN | L25: NOTES
C26: REP | D26: LOAD | E26: REP | F26: LOAD | G26: REP | H26: LOAD | I26: REP | J26: LOAD
A27: 1 | B27: =B16 | K27: =C27*D27+E27*F27+G27*H27+I27*J27
A28: 2 | B28: =B17 | K28: =C28*D28+E28*F28+G28*H28+I28*J28
A29: 3 | B29: =B18 | K29: =C29*D29+E29*F29+G29*H29+I29*J29
A30: 4 | B30: =B19 | K30: =C30*D30+E30*F30+G30*H30+I30*J30
B31: =B20
B32: =B21
A34: Exercise | F34: Set | G34: Rep | H34: RIR | I34: Tempo | J34: Rest
A35: ='Training Plan 1'!AC28 | F35: ='Training Plan 1'!AD28 | G35: ='Training Plan 1'!AE28 | H35: ='Training Plan 1'!AF28 | I35: ='Training Plan 1'!AG28 | J35: ='Training Plan 1'!AH28
A36: WEEK | B36: DATE | C36: SET 1 | E36: SET 2 | G36: SET 3 | I36: SET 4 | K36: TOTAL VOLUMN | L36: NOTES
C37: REP | D37: LOAD | E37: REP | F37: LOAD | G37: REP | H37: LOAD | I37: REP | J37: LOAD
A38: 1 | B38: =B27 | K38: =C38*D38+E38*F38+G38*H38+I38*J38
A39: 2 | B39: =B28 | K39: =C39*D39+E39*F39+G39*H39+I39*J39
A40: 3 | B40: =B29 | K40: =C40*D40+E40*F40+G40*H40+I40*J40
A41: 4 | B41: =B30 | K41: =C41*D41+E41*F41+G41*H41+I41*J41
B42: =B31
B43: =B32
A45: Exercise | F45: Set | G45: Rep | H45: RIR | I45: Tempo | J45: Rest
A46: ='Training Plan 1'!AC29 | F46: ='Training Plan 1'!AD29 | G46: ='Training Plan 1'!AE29 | H46: ='Training Plan 1'!AF29 | I46: ='Training Plan 1'!AG29 | J46: ='Training Plan 1'!AH29
A47: WEEK | B47: DATE | C47: SET 1 | E47: SET 2 | G47: SET 3 | I47: SET 4 | K47: TOTAL VOLUMN | L47: NOTES
...
